Workbook
Name Category: Sales_Data!$D$2:$D$101
Name CustomerType: Sales_Data!$L$2:$L$101
Name Discount: Sales_Data!$I$2:$I$101
Name Profit: Sales_Data!$K$2:$K$101
Name Rating: Sales_Data!$M$2:$M$101
Name Region: Sales_Data!$C$2:$C$101
Name Sales: Sales_Data!$J$2:$J$101
Name SalesRep: Sales_Data!$F$2:$F$101
Name UnitPrice: Sales_Data!$H$2:$H$101
Name Units: Sales_Data!$G$2:$G$101

Sheet Instructions
B2: Excel Analytics Practice Assignment
B5: Topics Covered
B6: • Conditional Formatting (Highlight Rules, Data Bars, Color Scales, Icon Sets, Duplicates)
B7: • IF (single condition)
B8: • Nested IF (multiple conditions)
B9: • IFS (multiple conditions, cleaner syntax)
B10: • SUMIF / SUMIFS
B11: • AVERAGEIF / AVERAGEIFS
B12: • COUNTIF / COUNTIFS
B13: • MINIFS / MAXIFS
B15: Instructions for Students
B16: 1. All questions use the dataset in the 'Sales_Data' sheet. Do not change the raw data.
... B26: G: Units | H: UnitPrice | I: Discount% | J: Sales | K: Profit | L: CustomerType | M: Rating(1-5)

Sheet Sales_Data_Formatted
A1: OrderID | B1: OrderDate | C1: Region | D1: Category | E1: Product | F1: SalesRep | G1: Units | H1: UnitPrice | I1: Discount% | J1: Sales | K1: Profit | L1: CustomerType | M1: Rating
A2: ORD1001 | B2: 45985 | C2: North | D2: Electronics | E2: Headphones | F2: Karan | G2: 8 | H2: 6408.28 | I2: 0 | J2: =G2*H2*(1-I2) -> 51266.24 | K2: =ROUND(J2*0.194,2) -> 9945.65 | L2: Retail | M2: 5
A3: ORD1002 | B3: 45673 | C3: North | D3: Furniture | E3: Study Table | F3: Ananya | G3: 18 | H3: 2029.89 | I3: 0.15 | J3: =G3*H3*(1-I3) -> 31057.317 | K3: =ROUND(J3*0.201,2) -> 6242.52 | L3: Wholesale | M3: 2
A4: ORD1003 | B4: 45800 | C4: North | D4: Furniture | E4: Sofa | F4: Vikram | G4: 9 | H4: 1652.67 | I4: 0.2 | J4: =G4*H4*(1-I4) -> 11899.224 | K4: =ROUND(J4*0.105,2) -> 1249.42 | L4: Wholesale | M4: 1
A5: ORD1004 | B5: 45707 | C5: East | D5: Clothing | E5: Cap | F5: Sneha | G5: 2 | H5: 2594.6 | I5: 0.1 | J5: =G5*H5*(1-I5) -> 4670.28 | K5: =ROUND(J5*0.101,2) -> 471.7 | L5: Retail | M5: 4
A6: ORD1005 | B6: 45808 | C6: East | D6: Stationery | E6: Pen Set | F6: Rohit | G6: 2 | H6: 2365.23 | I6: 0.2 | J6: =G6*H6*(1-I6) -> 3784.368 | K6: =ROUND(J6*0.311,2) -> 1176.94 | L6: Wholesale | M6: 1
A7: ORD1006 | B7: 45709 | C7: West | D7: Clothing | E7: Shoes | F7: Vikram | G7: 6 | H7: 1390.11 | I7: 0 | J7: =G7*H7*(1-I7) -> 8340.66 | K7: =ROUND(J7*0.244,2) -> 2035.12 | L7: Wholesale | M7: 1
A8: ORD1007 | B8: 45745 | C8: South | D8: Furniture | E8: Sofa | F8: Meera | G8: 9 | H8: 8908.85 | I8: 0.15 | J8: =G8*H8*(1-I8) -> 68152.702 | K8: =ROUND(J8*0.308,2) -> 20991.03 | L8: Retail | M8: 3
A9: ORD1008 | B9: 45686 | C9: South | D9: Electronics | E9: Headphones | F9: Meera | G9: 9 | H9: 3118.56 | I9: 0.1 | J9: =G9*H9*(1-I9) -> 25260.336 | K9: =ROUND(J9*0.257,2) -> 6491.91 | L9: Wholesale | M9: 2
A10: ORD1009 | B10: 45860 | C10: West | D10: Furniture | E10: Bookshelf | F10: Priya | G10: 8 | H10: 6781.4 | I10: 0.1 | J10: =G10*H10*(1-I10) -> 48826.08 | K10: =ROUND(J10*0.196,2) -> 9569.91 | L10: Wholesale | M10: 5
A11: ORD1010 | B11: 45956 | C11: West | D11: Clothing | E11: Jeans | F11: Priya | G11: 17 | H11: 1803.28 | I11: 0.2 | J11: =G11*H11*(1-I11) -> 24524.608 | K11: =ROUND(J11*0.121,2) -> 2967.48 | L11: Retail | M11: 1
A12: ORD1011 | B12: 45739 | C12: West | D12: Stationery | E12: Notebook | F12: Meera | G12: 13 | H12: 2146.23 | I12: 0.1 | J12: =G12*H12*(1-I12) -> 25110.891 | K12: =ROUND(J12*0.312,2) -> 7834.6 | L12: Wholesale | M12: 5
A13: ORD1012 | B13: 45663 | C13: North | D13: Stationery | E13: Backpack | F13: Vikram | G13: 4 | H13: 1133.23 | I13: 0 | J13: =G13*H13*(1-I13) -> 4532.92 | K13: =ROUND(J13*0.338,2) -> 1532.13 | L13: Wholesale | M13: 1
A14: ORD1013 | B14: 45792 | C14: South | D14: Stationery | E14: Notebook | F14: Sneha | G14: 21 | H14: 1850.67 | I14: 0 | J14: =G14*H14*(1-I14) -> 38864.07 | K14: =ROUND(J14*0.286,2) -> 11115.12 | L14: Retail | M14: 3
A15: ORD1014 | B15: 45934 | C15: North | D15: Stationery | E15: Backpack | F15: Arjun | G15: 1 | H15: 524.76 | I15: 0.05 | J15: =G15*H15*(1-I15) -> 498.522 | K15: =ROUND(J15*0.096,2) -> 47.86 | L15: Wholesale | M15: 2
A16: ORD1015 | B16: 45948 | C16: North | D16: Electronics | E16: Tablet | F16: Rohit | G16: 25 | H16: 24041.87 | I16: 0 | J16: =G16*H16*(1-I16) -> 601046.75 | K16: =ROUND(J16*0.336,2) -> 201951.71 | L16: Retail | M16: 4
A17: ORD1016 | B17: 45742 | C17: East | D17: Stationery | E17: Desk Organizer | F17: Meera | G17: 7 | H17: 3261.86 | I17: 0.2 | J17: =G17*H17*(1-I17) -> 18266.416 | K17: =ROUND(J17*0.188,2) -> 3434.09 | L17: Retail | M17: 3
A18: ORD1017 | B18: 46001 | C18: East | D18: Grocery | E18: Spices | F18: Arjun | G18: 4 | H18: 980.48 | I18: 0 | J18: =G18*H18*(1-I18) -> 3921.92 | K18: =ROUND(J18*0.239,2) -> 937.34 | L18: Wholesale | M18: 1
A19: ORD1018 | B19: 45775 | C19: South | D19: Electronics | E19: Laptop | F19: Ananya | G19: 8 | H19: 3172.9 | I19: 0 | J19: =G19*H19*(1-I19) -> 25383.2 | K19: =ROUND(J19*0.219,2) -> 5558.92 | L19: Wholesale | M19: 1
A20: ORD1019 | B20: 45800 | C20: West | D20: Furniture | E20: Bed Frame | F20: Priya | G20: 24 | H20: 8438.97 | I20: 0.1 | J20: =G20*H20*(1-I20) -> 182281.75 | K20: =ROUND(J20*0.292,2) -> 53226.27 | L20: Wholesale | M20: 2
A21: ORD1020 | B21: 45866 | C21: South | D21: Electronics | E21: Laptop | F21: Meera | G21: 12 | H21: 19147.5 | I21: 0.1 | J21: =G21*H21*(1-I21) -> 206793 | K21: =ROUND(J21*0.096,2) -> 19852.13 | L21: Retail | M21: 1
A22: ORD1021 | B22: 45831 | C22: North | D22: Furniture | E22: Study Table | F22: Karan | G22: 18 | H22: 4202.94 | I22: 0.1 | J22: =G22*H22*(1-I22) -> 68087.628 | K22: =ROUND(J22*0.205,2) -> 13957.96 | L22: Retail | M22: 3
A23: ORD1022 | B23: 45696 | C23: West | D23: Stationery | E23: Notebook | F23: Ananya | G23: 21 | H23: 3497.6 | I23: 0.2 | J23: =G23*H23*(1-I23) -> 58759.68 | K23: =ROUND(J23*0.33,2) -> 19390.69 | L23: Retail | M23: 1
A24: ORD1023 | B24: 45779 | C24: South | D24: Grocery | E24: Beverages | F24: Arjun | G24: 7 | H24: 3046.58 | I24: 0 | J24: =G24*H24*(1-I24) -> 21326.06 | K24: =ROUND(J24*0.081,2) -> 1727.41 | L24: Retail | M24: 4
A25: ORD1024 | B25: 45857 | C25: East | D25: Grocery | E25: Snack Pack | F25: Meera | G25: 23 | H25: 3357.01 | I25: 0.2 | J25: =G25*H25*(1-I25) -> 61768.984 | K25: =ROUND(J25*0.131,2) -> 8091.74 | L25: Wholesale | M25: 2
A26: ORD1025 | B26: 45769 | C26: North | D26: Stationery | E26: Desk Organizer | F26: Ananya | G26: 24 | H26: 1200.58 | I26: 0 | J26: =G26*H26*(1-I26) -> 28813.92 | K26: =ROUND(J26*0.328,2) -> 9450.97 | L26: Wholesale | M26: 5
A27: ORD1026 | B27: 45929 | C27: South | D27: Electronics | E27: Smartwatch | F27: Rohit | G27: 6 | H27: 3223.18 | I27: 0 | J27: =G27*H27*(1-I27) -> 19339.08 | K27: =ROUND(J27*0.112,2) -> 2165.98 | L27: Retail | M27: 4
A28: ORD1027 | B28: 45949 | C28: South | D28: Stationery | E28: Desk Organizer | F28: Ananya | G28: 20 | H28: 424.64 | I28: 0.15 | J28: =G28*H28*(1-I28) -> 7218.88 | K28: =ROUND(J28*0.135,2) -> 974.55 | L28: Wholesale | M28: 3
A29: ORD1028 | B29: 45818 | C29: South | D29: Clothing | E29: Shoes | F29: Priya | G29: 22 | H29: 2312.43 | I29: 0.1 | J29: =G29*H29*(1-I29) -> 45786.114 | K29: =ROUND(J29*0.083,2) -> 3800.25 | L29: Wholesale | M29: 1
A30: ORD1029 | B30: 45976 | C30: North | D30: Electronics | E30: Smartwatch | F30: Karan | G30: 17 | H30: 12044.24 | I30: 0.05 | J30: =G30*H30*(1-I30) -> 194514.48 | K30: =ROUND(J30*0.18,2) -> 35012.61 | L30: Retail | M30: 2
A31: ORD1030 | B31: 45738 | C31: West | D31: Stationery | E31: Backpack | F31: Ananya | G31: 22 | H31: 2887.3 | I31: 0.05 | J31: =G31*H31*(1-I31) -> 60344.57 | K31: =ROUND(J31*0.151,2) -> 9112.03 | L31: Retail | M31: 2
A32: ORD1031 | B32: 45712 | C32: South | D32: Clothing | E32: Jacket | F32: Karan | G32: 23 | H32: 1298.65 | I32: 0.15 | J32: =G32*H32*(1-I32) -> 25388.607 | K32: =ROUND(J32*0.212,2) -> 5382.38 | L32: Wholesale | M32: 5
A33: ORD1032 | B33: 45684 | C33: North | D33: Grocery | E33: Snack Pack | F33: Ananya | G33: 1 | H33: 1267.41 | I33: 0 | J33: =G33*H33*(1-I33) -> 1267.41 | K33: =ROUND(J33*0.28,2) -> 354.87 | L33: Wholesale | M33: 2
A34: ORD1033 | B34: 45940 | C34: West | D34: Stationery | E34: Notebook | F34: Rohit | G34: 3 | H34: 3315.92 | I34: 0.15 | J34: =G34*H34*(1-I34) -> 8455.596 | K34: =ROUND(J34*0.09,2) -> 761 | L34: Retail | M34: 5
A35: ORD1034 | B35: 45847 | C35: South | D35: Grocery | E35: Cooking Oil | F35: Ananya | G35: 10 | H35: 1371.58 | I35: 0.2 | J35: =G35*H35*(1-I35) -> 10972.64 | K35: =ROUND(J35*0.137,2) -> 1503.25 | L35: Retail | M35: 3
A36: ORD1035 | B36: 45785 | C36: North | D36: Clothing | E36: Cap | F36: Meera | G36: 20 | H36: 2660.75 | I36: 0 | J36: =G36*H36*(1-I36) -> 53215 | K36: =ROUND(J36*0.318,2) -> 16922.37 | L36: Retail | M36: 2
A37: ORD1036 | B37: 45670 | C37: South | D37: Clothing | E37: Shoes | F37: Karan | G37: 9 | H37: 683.31 | I37: 0.15 | J37: =G37*H37*(1-I37) -> 5227.3215 | K37: =ROUND(J37*0.315,2) -> 1646.61 | L37: Retail | M37: 4
A38: ORD1037 | B38: 45898 | C38: South | D38: Furniture | E38: Sofa | F38: Vikram | G38: 10 | H38: 7438.67 | I38: 0.2 | J38: =G38*H38*(1-I38) -> 59509.36 | K38: =ROUND(J38*0.086,2) -> 5117.8 | L38: Retail | M38: 2
A39: ORD1038 | B39: 45756 | C39: West | D39: Clothing | E39: Jacket | F39: Rohit | G39: 25 | H39: 1085.07 | I39: 0.15 | J39: =G39*H39*(1-I39) -> 23057.737 | K39: =ROUND(J39*0.169,2) -> 3896.76 | L39: Wholesale | M39: 5
A40: ORD1039 | B40: 45672 | C40: North | D40: Clothing | E40: Jeans | F40: Sneha | G40: 2 | H40: 513.15 | I40: 0.1 | J40: =G40*H40*(1-I40) -> 923.67 | K40: =ROUND(J40*0.198,2) -> 182.89 | L40: Wholesale | M40: 3
...

Sheet Sales_Data
A1: OrderID | B1: OrderDate | C1: Region | D1: Category | E1: Product | F1: SalesRep | G1: Units | H1: UnitPrice | I1: Discount% | J1: Sales | K1: Profit | L1: CustomerType | M1: Rating
A2: ORD1001 | B2: 45985 | C2: North | D2: Electronics | E2: Headphones | F2: Karan | G2: 8 | H2: 6408.28 | I2: 0 | J2: =G2*H2*(1-I2) -> 51266.24 | K2: =ROUND(J2*0.194,2) -> 9945.65 | L2: Retail | M2: 5
A3: ORD1002 | B3: 45673 | C3: North | D3: Furniture | E3: Study Table | F3: Ananya | G3: 18 | H3: 2029.89 | I3: 0.15 | J3: =G3*H3*(1-I3) -> 31057.317 | K3: =ROUND(J3*0.201,2) -> 6242.52 | L3: Wholesale | M3: 2
A4: ORD1003 | B4: 45800 | C4: North | D4: Furniture | E4: Sofa | F4: Vikram | G4: 9 | H4: 1652.67 | I4: 0.2 | J4: =G4*H4*(1-I4) -> 11899.224 | K4: =ROUND(J4*0.105,2) -> 1249.42 | L4: Wholesale | M4: 1
A5: ORD1004 | B5: 45707 | C5: East | D5: Clothing | E5: Cap | F5: Sneha | G5: 2 | H5: 2594.6 | I5: 0.1 | J5: =G5*H5*(1-I5) -> 4670.28 | K5: =ROUND(J5*0.101,2) -> 471.7 | L5: Retail | M5: 4
A6: ORD1005 | B6: 45808 | C6: East | D6: Stationery | E6: Pen Set | F6: Rohit | G6: 2 | H6: 2365.23 | I6: 0.2 | J6: =G6*H6*(1-I6) -> 3784.368 | K6: =ROUND(J6*0.311,2) -> 1176.94 | L6: Wholesale | M6: 1
A7: ORD1006 | B7: 45709 | C7: West | D7: Clothing | E7: Shoes | F7: Vikram | G7: 6 | H7: 1390.11 | I7: 0 | J7: =G7*H7*(1-I7) -> 8340.66 | K7: =ROUND(J7*0.244,2) -> 2035.12 | L7: Wholesale | M7: 1
A8: ORD1007 | B8: 45745 | C8: South | D8: Furniture | E8: Sofa | F8: Meera | G8: 9 | H8: 8908.85 | I8: 0.15 | J8: =G8*H8*(1-I8) -> 68152.702 | K8: =ROUND(J8*0.308,2) -> 20991.03 | L8: Retail | M8: 3
A9: ORD1008 | B9: 45686 | C9: South | D9: Electronics | E9: Headphones | F9: Meera | G9: 9 | H9: 3118.56 | I9: 0.1 | J9: =G9*H9*(1-I9) -> 25260.336 | K9: =ROUND(J9*0.257,2) -> 6491.91 | L9: Wholesale | M9: 2
A10: ORD1009 | B10: 45860 | C10: West | D10: Furniture | E10: Bookshelf | F10: Priya | G10: 8 | H10: 6781.4 | I10: 0.1 | J10: =G10*H10*(1-I10) -> 48826.08 | K10: =ROUND(J10*0.196,2) -> 9569.91 | L10: Wholesale | M10: 5
A11: ORD1010 | B11: 45956 | C11: West | D11: Clothing | E11: Jeans | F11: Priya | G11: 17 | H11: 1803.28 | I11: 0.2 | J11: =G11*H11*(1-I11) -> 24524.608 | K11: =ROUND(J11*0.121,2) -> 2967.48 | L11: Retail | M11: 1
A12: ORD1011 | B12: 45739 | C12: West | D12: Stationery | E12: Notebook | F12: Meera | G12: 13 | H12: 2146.23 | I12: 0.1 | J12: =G12*H12*(1-I12) -> 25110.891 | K12: =ROUND(J12*0.312,2) -> 7834.6 | L12: Wholesale | M12: 5
A13: ORD1012 | B13: 45663 | C13: North | D13: Stationery | E13: Backpack | F13: Vikram | G13: 4 | H13: 1133.23 | I13: 0 | J13: =G13*H13*(1-I13) -> 4532.92 | K13: =ROUND(J13*0.338,2) -> 1532.13 | L13: Wholesale | M13: 1
A14: ORD1013 | B14: 45792 | C14: South | D14: Stationery | E14: Notebook | F14: Sneha | G14: 21 | H14: 1850.67 | I14: 0 | J14: =G14*H14*(1-I14) -> 38864.07 | K14: =ROUND(J14*0.286,2) -> 11115.12 | L14: Retail | M14: 3
A15: ORD1014 | B15: 45934 | C15: North | D15: Stationery | E15: Backpack | F15: Arjun | G15: 1 | H15: 524.76 | I15: 0.05 | J15: =G15*H15*(1-I15) -> 498.522 | K15: =ROUND(J15*0.096,2) -> 47.86 | L15: Wholesale | M15: 2
A16: ORD1015 | B16: 45948 | C16: North | D16: Electronics | E16: Tablet | F16: Rohit | G16: 25 | H16: 24041.87 | I16: 0 | J16: =G16*H16*(1-I16) -> 601046.75 | K16: =ROUND(J16*0.336,2) -> 201951.71 | L16: Retail | M16: 4
A17: ORD1016 | B17: 45742 | C17: East | D17: Stationery | E17: Desk Organizer | F17: Meera | G17: 7 | H17: 3261.86 | I17: 0.2 | J17: =G17*H17*(1-I17) -> 18266.416 | K17: =ROUND(J17*0.188,2) -> 3434.09 | L17: Retail | M17: 3
A18: ORD1017 | B18: 46001 | C18: East | D18: Grocery | E18: Spices | F18: Arjun | G18: 4 | H18: 980.48 | I18: 0 | J18: =G18*H18*(1-I18) -> 3921.92 | K18: =ROUND(J18*0.239,2) -> 937.34 | L18: Wholesale | M18: 1
A19: ORD1018 | B19: 45775 | C19: South | D19: Electronics | E19: Laptop | F19: Ananya | G19: 8 | H19: 3172.9 | I19: 0 | J19: =G19*H19*(1-I19) -> 25383.2 | K19: =ROUND(J19*0.219,2) -> 5558.92 | L19: Wholesale | M19: 1
A20: ORD1019 | B20: 45800 | C20: West | D20: Furniture | E20: Bed Frame | F20: Priya | G20: 24 | H20: 8438.97 | I20: 0.1 | J20: =G20*H20*(1-I20) -> 182281.75 | K20: =ROUND(J20*0.292,2) -> 53226.27 | L20: Wholesale | M20: 2
A21: ORD1020 | B21: 45866 | C21: South | D21: Electronics | E21: Laptop | F21: Meera | G21: 12 | H21: 19147.5 | I21: 0.1 | J21: =G21*H21*(1-I21) -> 206793 | K21: =ROUND(J21*0.096,2) -> 19852.13 | L21: Retail | M21: 1
A22: ORD1021 | B22: 45831 | C22: North | D22: Furniture | E22: Study Table | F22: Karan | G22: 18 | H22: 4202.94 | I22: 0.1 | J22: =G22*H22*(1-I22) -> 68087.628 | K22: =ROUND(J22*0.205,2) -> 13957.96 | L22: Retail | M22: 3
A23: ORD1022 | B23: 45696 | C23: West | D23: Stationery | E23: Notebook | F23: Ananya | G23: 21 | H23: 3497.6 | I23: 0.2 | J23: =G23*H23*(1-I23) -> 58759.68 | K23: =ROUND(J23*0.33,2) -> 19390.69 | L23: Retail | M23: 1
A24: ORD1023 | B24: 45779 | C24: South | D24: Grocery | E24: Beverages | F24: Arjun | G24: 7 | H24: 3046.58 | I24: 0 | J24: =G24*H24*(1-I24) -> 21326.06 | K24: =ROUND(J24*0.081,2) -> 1727.41 | L24: Retail | M24: 4
A25: ORD1024 | B25: 45857 | C25: East | D25: Grocery | E25: Snack Pack | F25: Meera | G25: 23 | H25: 3357.01 | I25: 0.2 | J25: =G25*H25*(1-I25) -> 61768.984 | K25: =ROUND(J25*0.131,2) -> 8091.74 | L25: Wholesale | M25: 2
A26: ORD1025 | B26: 45769 | C26: North | D26: Stationery | E26: Desk Organizer | F26: Ananya | G26: 24 | H26: 1200.58 | I26: 0 | J26: =G26*H26*(1-I26) -> 28813.92 | K26: =ROUND(J26*0.328,2) -> 9450.97 | L26: Wholesale | M26: 5
A27: ORD1026 | B27: 45929 | C27: South | D27: Electronics | E27: Smartwatch | F27: Rohit | G27: 6 | H27: 3223.18 | I27: 0 | J27: =G27*H27*(1-I27) -> 19339.08 | K27: =ROUND(J27*0.112,2) -> 2165.98 | L27: Retail | M27: 4
A28: ORD1027 | B28: 45949 | C28: South | D28: Stationery | E28: Desk Organizer | F28: Ananya | G28: 20 | H28: 424.64 | I28: 0.15 | J28: =G28*H28*(1-I28) -> 7218.88 | K28: =ROUND(J28*0.135,2) -> 974.55 | L28: Wholesale | M28: 3
A29: ORD1028 | B29: 45818 | C29: South | D29: Clothing | E29: Shoes | F29: Priya | G29: 22 | H29: 2312.43 | I29: 0.1 | J29: =G29*H29*(1-I29) -> 45786.114 | K29: =ROUND(J29*0.083,2) -> 3800.25 | L29: Wholesale | M29: 1
A30: ORD1029 | B30: 45976 | C30: North | D30: Electronics | E30: Smartwatch | F30: Karan | G30: 17 | H30: 12044.24 | I30: 0.05 | J30: =G30*H30*(1-I30) -> 194514.48 | K30: =ROUND(J30*0.18,2) -> 35012.61 | L30: Retail | M30: 2
A31: ORD1030 | B31: 45738 | C31: West | D31: Stationery | E31: Backpack | F31: Ananya | G31: 22 | H31: 2887.3 | I31: 0.05 | J31: =G31*H31*(1-I31) -> 60344.57 | K31: =ROUND(J31*0.151,2) -> 9112.03 | L31: Retail | M31: 2
A32: ORD1031 | B32: 45712 | C32: South | D32: Clothing | E32: Jacket | F32: Karan | G32: 23 | H32: 1298.65 | I32: 0.15 | J32: =G32*H32*(1-I32) -> 25388.607 | K32: =ROUND(J32*0.212,2) -> 5382.38 | L32: Wholesale | M32: 5
A33: ORD1032 | B33: 45684 | C33: North | D33: Grocery | E33: Snack Pack | F33: Ananya | G33: 1 | H33: 1267.41 | I33: 0 | J33: =G33*H33*(1-I33) -> 1267.41 | K33: =ROUND(J33*0.28,2) -> 354.87 | L33: Wholesale | M33: 2
A34: ORD1033 | B34: 45940 | C34: West | D34: Stationery | E34: Notebook | F34: Rohit | G34: 3 | H34: 3315.92 | I34: 0.15 | J34: =G34*H34*(1-I34) -> 8455.596 | K34: =ROUND(J34*0.09,2) -> 761 | L34: Retail | M34: 5
A35: ORD1034 | B35: 45847 | C35: South | D35: Grocery | E35: Cooking Oil | F35: Ananya | G35: 10 | H35: 1371.58 | I35: 0.2 | J35: =G35*H35*(1-I35) -> 10972.64 | K35: =ROUND(J35*0.137,2) -> 1503.25 | L35: Retail | M35: 3
A36: ORD1035 | B36: 45785 | C36: North | D36: Clothing | E36: Cap | F36: Meera | G36: 20 | H36: 2660.75 | I36: 0 | J36: =G36*H36*(1-I36) -> 53215 | K36: =ROUND(J36*0.318,2) -> 16922.37 | L36: Retail | M36: 2
A37: ORD1036 | B37: 45670 | C37: South | D37: Clothing | E37: Shoes | F37: Karan | G37: 9 | H37: 683.31 | I37: 0.15 | J37: =G37*H37*(1-I37) -> 5227.3215 | K37: =ROUND(J37*0.315,2) -> 1646.61 | L37: Retail | M37: 4
A38: ORD1037 | B38: 45898 | C38: South | D38: Furniture | E38: Sofa | F38: Vikram | G38: 10 | H38: 7438.67 | I38: 0.2 | J38: =G38*H38*(1-I38) -> 59509.36 | K38: =ROUND(J38*0.086,2) -> 5117.8 | L38: Retail | M38: 2
A39: ORD1038 | B39: 45756 | C39: West | D39: Clothing | E39: Jacket | F39: Rohit | G39: 25 | H39: 1085.07 | I39: 0.15 | J39: =G39*H39*(1-I39) -> 23057.737 | K39: =ROUND(J39*0.169,2) -> 3896.76 | L39: Wholesale | M39: 5
A40: ORD1039 | B40: 45672 | C40: North | D40: Clothing | E40: Jeans | F40: Sneha | G40: 2 | H40: 513.15 | I40: 0.1 | J40: =G40*H40*(1-I40) -> 923.67 | K40: =ROUND(J40*0.198,2) -> 182.89 | L40: Wholesale | M40: 3
...

Sheet Assignment_Questions
A1: Q.No | B1: Topic | C1: Question | D1: Your Answer (type formula here) | F1: 1 | G1: 2 | H1: 3 | I1: 4 | J1: 5 | K1: 6 | L1: 7 | M1: 8 | N1: 9
A2: 1 | B2: IF | C2: In cell F2 area (use your Answer column), write a formula that returns "High" if a single order's Sales (Sales_Data!J2) is greater than 20000, otherwise "Low". | F2: {=IF(Sales>20000,"High","Low")} -> High | G2: {=IF(Rating>=4,"Good","Needs Improvement")} -> Good | H2: {=IF(CustomerType="Wholesale","Wholesale Deal","Retail Deal")} -> Retail Deal | I2: {=IF(Sales>20000,"Large",IF(Sales>=5000,"Medium",IF(Sales<5000,"Small")))} -> Large | J2: {=IF(Rating=5,"Excellent",IF(Rating>=3,"Good",IF(Rating<=2,"Poor")))} -> Excellent | K2: {=IF(Discount=0,"No Discount",IF(Discount>10%,"High",IF(Discount<=10%,"Low")))} -> No Discount | L2: {=_xlfn.IFS(Sales>20000,"Large",Sales>=5000,"Medium",Sales<5000,"Small")} -> Large | M2: {=_xlfn.IFS(Units>=15,"Bulk Order",Units>=5,"Standard Order",Units<5,"Small Order")} -> Standard Order | N2: {=_xlfn.IFS(Region="North","Zone A",Region="South","Zone B",Region="East","Zone C",Region="West","Zone D")} -> Zone A
A3: 2 | B3: IF | C3: Write a formula that checks Sales_Data!M2 (Rating) and returns "Good" if the rating is 4 or above, otherwise "Needs Improvement". | F3: High | G3: Needs Improvement | H3: Wholesale Deal | I3: Large | J3: Poor | K3: High | L3: Large | M3: Bulk Order | N3: Zone A
A4: 3 | B4: IF | C4: Write a formula that returns "Wholesale Deal" if Sales_Data!L2 equals "Wholesale", otherwise "Retail Deal". | F4: Low | G4: Needs Improvement | H4: Wholesale Deal | I4: Medium | J4: Poor | K4: High | L4: Medium | M4: Standard Order | N4: Zone A
A5: 4 | B5: Nested IF | C5: Write a nested IF formula that classifies Sales_Data!J2 (Sales) into "Small" (< 5000), "Medium" (5000 to 20000), or "Large" (> 20000). | F5: Low | G5: Good | H5: Retail Deal | I5: Small | J5: Good | K5: Low | L5: Small | M5: Small Order | N5: Zone C
A6: 5 | B6: Nested IF | C6: Write a nested IF formula that grades Sales_Data!M2 (Rating) as "Excellent" (5), "Good" (3 or 4), or "Poor" (1 or 2). | F6: Low | G6: Needs Improvement | H6: Wholesale Deal | I6: Small | J6: Poor | K6: High | L6: Small | M6: Small Order | N6: Zone C
A7: 6 | B7: Nested IF | C7: Write a nested IF formula that assigns a Discount Tier to Sales_Data!I2 (Discount%): "No Discount" (0), "Low" (up to 10%), "High" (above 10%). | F7: Low | G7: Needs Improvement | H7: Wholesale Deal | I7: Medium | J7: Poor | K7: No Discount | L7: Medium | M7: Standard Order | N7: Zone D
A8: 7 | B8: IFS | C8: Rewrite Question 4 (Sales classification into Small/Medium/Large) using the IFS function instead of nested IF. | F8: High | G8: Needs Improvement | H8: Retail Deal | I8: Large | J8: Good | K8: High | L8: Large | M8: Standard Order | N8: Zone B
A9: 8 | B9: IFS | C9: Using IFS, classify Sales_Data!G2 (Units) as "Bulk Order" (>=15), "Standard Order" (5 to 14), or "Small Order" (<5). | F9: High | G9: Needs Improvement | H9: Wholesale Deal | I9: Large | J9: Poor | K9: Low | L9: Large | M9: Standard Order | N9: Zone B
A10: 9 | B10: IFS | C10: Using IFS, return the Region-wise shift label for Sales_Data!C2: "North" -> "Zone A", "South" -> "Zone B", "East" -> "Zone C", "West" -> "Zone D". | F10: High | G10: Good | H10: Wholesale Deal | I10: Large | J10: Excellent | K10: Low | L10: Large | M10: Standard Order | N10: Zone D
A11: 10 | B11: SUMIF | C11: Find the total Sales for the "Electronics" category using SUMIF. | D11: =SUMIF(Category,"Electronics",Sales) -> 3660496 | F11: High | G11: Needs Improvement | H11: Retail Deal | I11: Large | J11: Poor | K11: High | L11: Large | M11: Bulk Order | N11: Zone D
A12: 11 | B12: SUMIF | C12: Find the total Profit for orders placed in the "North" region using SUMIF. | D12: =SUMIF(Region,"North",Profit) -> 498720.05 | F12: High | G12: Good | H12: Wholesale Deal | I12: Large | J12: Excellent | K12: Low | L12: Large | M12: Standard Order | N12: Zone D
A13: 12 | B13: SUMIF | C13: Find the total Sales for all orders with Rating equal to 5 using SUMIF. | D13: =SUMIF(Rating,5,Sales) -> 790492.62 | F13: Low | G13: Needs Improvement | H13: Wholesale Deal | I13: Small | J13: Poor | K13: No Discount | L13: Small | M13: Small Order | N13: Zone A
A14: 13 | B14: SUMIFS | C14: Find the total Sales for the "Electronics" category in the "North" region using SUMIFS. | D14: =SUMIFS(Sales,Category,"Electronics",Region,"North") -> 1205581.2 | F14: High | G14: Needs Improvement | H14: Retail Deal | I14: Large | J14: Good | K14: No Discount | L14: Large | M14: Bulk Order | N14: Zone B
A15: 14 | B15: SUMIFS | C15: Find the total Profit for "Wholesale" customers with Sales greater than 10000, using SUMIFS. | D15: =SUMIFS(Profit,CustomerType,"Wholesale",Sales,">10000") -> 566137.35 | F15: Low | G15: Needs Improvement | H15: Wholesale Deal | I15: Small | J15: Poor | K15: Low | L15: Small | M15: Small Order | N15: Zone A
A16: 15 | B16: SUMIFS | C16: Find total Sales for orders from SalesRep "Ananya" in the "Clothing" category with a Discount% greater than 0, using SUMIFS. | D16: =SUMIFS(Sales,SalesRep,"Ananya",Category,"Clothing",Discount,">0") -> 42341.28 | F16: High | G16: Good | H16: Retail Deal | I16: Large | J16: Good | K16: No Discount | L16: Large | M16: Bulk Order | N16: Zone A
A17: 16 | B17: AVERAGEIF | C17: Find the average UnitPrice for the "Furniture" category using AVERAGEIF. | D17: =AVERAGEIF(Category,"Furniture",UnitPrice) -> 5379.4805 | F17: Low | G17: Needs Improvement | H17: Retail Deal | I17: Medium | J17: Good | K17: High | L17: Medium | M17: Standard Order | N17: Zone C
A18: 17 | B18: AVERAGEIF | C18: Find the average Rating for orders from the "West" region using AVERAGEIF. | D18: =AVERAGEIF(Region,"West",Rating) -> 2.9130435 | F18: Low | G18: Needs Improvement | H18: Wholesale Deal | I18: Small | J18: Poor | K18: No Discount | L18: Small | M18: Small Order | N18: Zone C
A19: 18 | B19: AVERAGEIFS | C19: Find the average Sales for "Retail" customers in the "Grocery" category using AVERAGEIFS. | D19: =AVERAGEIFS(Sales,CustomerType,"Retail",Category,"Grocery") -> 21427.682 | F19: High | G19: Needs Improvement | H19: Wholesale Deal | I19: Large | J19: Poor | K19: No Discount | L19: Large | M19: Standard Order | N19: Zone B
A20: 19 | B20: AVERAGEIFS | C20: Find the average Profit for orders in the "South" region with Units greater than 10, using AVERAGEIFS. | D20: =AVERAGEIFS(Profit,Region,"South",Units,">10") -> 17683.03 | F20: High | G20: Needs Improvement | H20: Wholesale Deal | I20: Large | J20: Poor | K20: Low | L20: Large | M20: Bulk Order | N20: Zone D
A21: 20 | B21: COUNTIF | C21: Count how many orders belong to the "Stationery" category using COUNTIF. | D21: =COUNTIF(Category,"Stationery") -> 21 | F21: High | G21: Needs Improvement | H21: Retail Deal | I21: Large | J21: Poor | K21: Low | L21: Large | M21: Standard Order | N21: Zone B
A22: 21 | B22: COUNTIF | C22: Count how many orders have a Rating of 5 using COUNTIF. | D22: =COUNTIF(Rating,"=5") -> 17 | F22: High | G22: Needs Improvement | H22: Retail Deal | I22: Large | J22: Good | K22: Low | L22: Large | M22: Bulk Order | N22: Zone A
A23: 22 | B23: COUNTIF | C23: Count how many orders have Sales greater than 15000 using COUNTIF. | D23: =COUNTIF(Sales,">15000") -> 76 | F23: High | G23: Needs Improvement | H23: Retail Deal | I23: Large | J23: Poor | K23: High | L23: Large | M23: Bulk Order | N23: Zone D
A24: 23 | B24: COUNTIFS | C24: Count how many "Wholesale" orders came from the "East" region using COUNTIFS. | D24: =COUNTIFS(CustomerType,"Wholesale",Region,"East") -> 9 | F24: High | G24: Good | H24: Retail Deal | I24: Large | J24: Good | K24: No Discount | L24: Large | M24: Standard Order | N24: Zone B
A25: 24 | B25: COUNTIFS | C25: Count how many orders in the "Electronics" category have a Discount% greater than 10%, using COUNTIFS. | D25: =COUNTIFS(Category,"Electronics",Discount,">10%") -> 2 | F25: High | G25: Needs Improvement | H25: Wholesale Deal | I25: Large | J25: Poor | K25: High | L25: Large | M25: Bulk Order | N25: Zone C
A26: 25 | B26: MINIFS | C26: Find the minimum Sales value for the "Clothing" category using MINIFS. | D26: =_xlfn.MINIFS(Sales,Category,"Clothing") -> 923.67 | F26: High | G26: Good | H26: Wholesale Deal | I26: Large | J26: Excellent | K26: No Discount | L26: Large | M26: Bulk Order | N26: Zone A
A27: 26 | B27: MINIFS | C27: Find the minimum UnitPrice among orders from the "North" region using MINIFS. | D27: =_xlfn.MINIFS(UnitPrice,Region,"North") -> 298.69 | F27: Low | G27: Good | H27: Retail Deal | I27: Medium | J27: Good | K27: No Discount | L27: Medium | M27: Standard Order | N27: Zone B
A28: 27 | B28: MAXIFS | C28: Find the maximum Profit for the "Electronics" category using MAXIFS. | D28: =_xlfn.MAXIFS(Profit,Category,"Electronics") -> 201951.71 | F28: Low | G28: Needs Improvement | H28: Wholesale Deal | I28: Medium | J28: Good | K28: High | L28: Medium | M28: Bulk Order | N28: Zone B
A29: 28 | B29: MAXIFS | C29: Find the maximum Sales value among "Wholesale" customers in the "South" region, using MAXIFS. | D29: =_xlfn.MAXIFS(Sales,CustomerType,"Wholesale",Region,"South") -> 636284.16 | F29: High | G29: Needs Improvement | H29: Wholesale Deal | I29: Large | J29: Poor | K29: Low | L29: Large | M29: Bulk Order | N29: Zone B
F30: High | G30: Needs Improvement | H30: Retail Deal | I30: Large | J30: Poor | K30: Low | L30: Large | M30: Bulk Order | N30: Zone A
F31: High | G31: Needs Improvement | H31: Retail Deal | I31: Large | J31: Poor | K31: Low | L31: Large | M31: Bulk Order | N31: Zone D
F32: High | G32: Good | H32: Wholesale Deal | I32: Large | J32: Excellent | K32: High | L32: Large | M32: Bulk Order | N32: Zone B
F33: Low | G33: Needs Improvement | H33: Wholesale Deal | I33: Small | J33: Poor | K33: No Discount | L33: Small | M33: Small Order | N33: Zone A
F34: Low | G34: Good | H34: Retail Deal | I34: Medium | J34: Excellent | K34: High | L34: Medium | M34: Small Order | N34: Zone D
F35: Low | G35: Needs Improvement | H35: Retail Deal | I35: Medium | J35: Good | K35: High | L35: Medium | M35: Standard Order | N35: Zone B
F36: High | G36: Needs Improvement | H36: Retail Deal | I36: Large | J36: Poor | K36: No Discount | L36: Large | M36: Bulk Order | N36: Zone A
F37: Low | G37: Good | H37: Retail Deal | I37: Medium | J37: Good | K37: High | L37: Medium | M37: Standard Order | N37: Zone B
F38: High | G38: Needs Improvement | H38: Retail Deal | I38: Large | J38: Poor | K38: High | L38: Large | M38: Standard Order | N38: Zone B
F39: High | G39: Good | H39: Wholesale Deal | I39: Large | J39: Excellent | K39: High | L39: Large | M39: Bulk Order | N39: Zone D
F40: Low | G40: Needs Improvement | H40: Wholesale Deal | I40: Small | J40: Good | K40: Low | L40: Small | M40: Small Order | N40: Zone A
...

Sheet Conditional_Formatting_Tasks
A1: Conditional Formatting Tasks
A2: Perform these tasks on a COPY of the Sales_Data sheet. Right-click the 'Sales_Data' tab, choose 'Move or Copy', tick 'Create a copy', and rename it 'Sales_Data_Formatted'. Apply each rule below using Home > Conditional Formatting.
A4: 1 | B4: Highlight the Sales column (J) in GREEN if the value is greater than 20000, and in RED if less than 5000.
A5: 2 | B5: Apply a Data Bar to the Profit column (K) so you can visually compare profit across all orders.
A6: 3 | B6: Apply a 3-Color Scale to the Rating column (M) so low ratings appear red and high ratings appear green.
A7: 4 | B7: Use an Icon Set (3 arrows) on the Discount% column (I) to show low, medium, and high discounts.
A8: 5 | B8: Highlight duplicate values in the Product column (E) using 'Highlight Cell Rules > Duplicate Values'.
A9: 6 | B9: Highlight the entire row in light yellow wherever CustomerType (L) = "Wholesale", using a formula-based rule (e.g. =$L2="Wholesale").
A10: 7 | B10: Highlight the OrderDate cell (B) in orange for any order placed in the month of December.

Sheet Answer_Key (Trainer Only)
A1: Q.No | B1: Topic | C1: Question | D1: Model Answer / Formula
A2: 1 | B2: IF | C2: In cell F2 area (use your Answer column), write a formula that returns "High" if a single order's Sales (Sales_Data!J2) is greater than 20000, otherwise "Low". | D2: =IF(Sales_Data!J2>20000,"High","Low") -> High
A3: 2 | B3: IF | C3: Write a formula that checks Sales_Data!M2 (Rating) and returns "Good" if the rating is 4 or above, otherwise "Needs Improvement". | D3: =IF(Sales_Data!M2>=4,"Good","Needs Improvement") -> Good
A4: 3 | B4: IF | C4: Write a formula that returns "Wholesale Deal" if Sales_Data!L2 equals "Wholesale", otherwise "Retail Deal". | D4: =IF(Sales_Data!L2="Wholesale","Wholesale Deal","Retail Deal") -> Retail Deal
A5: 4 | B5: Nested IF | C5: Write a nested IF formula that classifies Sales_Data!J2 (Sales) into "Small" (< 5000), "Medium" (5000 to 20000), or "Large" (> 20000). | D5: =IF(Sales_Data!J2<5000,"Small",IF(Sales_Data!J2<=20000,"Medium","Large")) -> Large
A6: 5 | B6: Nested IF | C6: Write a nested IF formula that grades Sales_Data!M2 (Rating) as "Excellent" (5), "Good" (3 or 4), or "Poor" (1 or 2). | D6: =IF(Sales_Data!M2=5,"Excellent",IF(Sales_Data!M2>=3,"Good","Poor")) -> Excellent
A7: 6 | B7: Nested IF | C7: Write a nested IF formula that assigns a Discount Tier to Sales_Data!I2 (Discount%): "No Discount" (0), "Low" (up to 10%), "High" (above 10%). | D7: =IF(Sales_Data!I2=0,"No Discount",IF(Sales_Data!I2<=0.1,"Low","High")) -> No Discount
A8: 7 | B8: IFS | C8: Rewrite Question 4 (Sales classification into Small/Medium/Large) using the IFS function instead of nested IF. | D8: =_xlfn.IFS(Sales_Data!J2<5000,"Small",Sales_Data!J2<=20000,"Medium",Sales_Data!J2>20000,"Large") -> Large
A9: 8 | B9: IFS | C9: Using IFS, classify Sales_Data!G2 (Units) as "Bulk Order" (>=15), "Standard Order" (5 to 14), or "Small Order" (<5). | D9: =_xlfn.IFS(Sales_Data!G2>=15,"Bulk Order",Sales_Data!G2>=5,"Standard Order",Sales_Data!G2<5,"Small Order") -> Standard Order
A10: 9 | B10: IFS | C10: Using IFS, return the Region-wise shift label for Sales_Data!C2: "North" -> "Zone A", "South" -> "Zone B", "East" -> "Zone C", "West" -> "Zone D". | D10: =_xlfn.IFS(Sales_Data!C2="North","Zone A",Sales_Data!C2="South","Zone B",Sales_Data!C2="East","Zone C",Sales_Data!C2="West","Zone D") -> Zone A
A11: 10 | B11: SUMIF | C11: Find the total Sales for the "Electronics" category using SUMIF. | D11: =SUMIF(Sales_Data!D:D,"Electronics",Sales_Data!J:J) -> 3660496
A12: 11 | B12: SUMIF | C12: Find the total Profit for orders placed in the "North" region using SUMIF. | D12: =SUMIF(Sales_Data!C:C,"North",Sales_Data!K:K) -> 498720.05
A13: 12 | B13: SUMIF | C13: Find the total Sales for all orders with Rating equal to 5 using SUMIF. | D13: =SUMIF(Sales_Data!M:M,5,Sales_Data!J:J) -> 790492.62
A14: 13 | B14: SUMIFS | C14: Find the total Sales for the "Electronics" category in the "North" region using SUMIFS. | D14: =SUMIFS(Sales_Data!J:J,Sales_Data!D:D,"Electronics",Sales_Data!C:C,"North") -> 1205581.2
A15: 14 | B15: SUMIFS | C15: Find the total Profit for "Wholesale" customers with Sales greater than 10000, using SUMIFS. | D15: =SUMIFS(Sales_Data!K:K,Sales_Data!L:L,"Wholesale",Sales_Data!J:J,">10000") -> 566137.35
A16: 15 | B16: SUMIFS | C16: Find total Sales for orders from SalesRep "Ananya" in the "Clothing" category with a Discount% greater than 0, using SUMIFS. | D16: =SUMIFS(Sales_Data!J:J,Sales_Data!F:F,"Ananya",Sales_Data!D:D,"Clothing",Sales_Data!I:I,">0") -> 42341.28
A17: 16 | B17: AVERAGEIF | C17: Find the average UnitPrice for the "Furniture" category using AVERAGEIF. | D17: =AVERAGEIF(Sales_Data!D:D,"Furniture",Sales_Data!H:H) -> 5379.4805
A18: 17 | B18: AVERAGEIF | C18: Find the average Rating for orders from the "West" region using AVERAGEIF. | D18: =AVERAGEIF(Sales_Data!C:C,"West",Sales_Data!M:M) -> 2.9130435
A19: 18 | B19: AVERAGEIFS | C19: Find the average Sales for "Retail" customers in the "Grocery" category using AVERAGEIFS. | D19: =AVERAGEIFS(Sales_Data!J:J,Sales_Data!L:L,"Retail",Sales_Data!D:D,"Grocery") -> 21427.682
A20: 19 | B20: AVERAGEIFS | C20: Find the average Profit for orders in the "South" region with Units greater than 10, using AVERAGEIFS. | D20: =AVERAGEIFS(Sales_Data!K:K,Sales_Data!C:C,"South",Sales_Data!G:G,">10") -> 17683.03
A21: 20 | B21: COUNTIF | C21: Count how many orders belong to the "Stationery" category using COUNTIF. | D21: =COUNTIF(Sales_Data!D:D,"Stationery") -> 21
A22: 21 | B22: COUNTIF | C22: Count how many orders have a Rating of 5 using COUNTIF. | D22: =COUNTIF(Sales_Data!M:M,5) -> 17
A23: 22 | B23: COUNTIF | C23: Count how many orders have Sales greater than 15000 using COUNTIF. | D23: =COUNTIF(Sales_Data!J:J,">15000") -> 76
A24: 23 | B24: COUNTIFS | C24: Count how many "Wholesale" orders came from the "East" region using COUNTIFS. | D24: =COUNTIFS(Sales_Data!L:L,"Wholesale",Sales_Data!C:C,"East") -> 9
A25: 24 | B25: COUNTIFS | C25: Count how many orders in the "Electronics" category have a Discount% greater than 10%, using COUNTIFS. | D25: =COUNTIFS(Sales_Data!D:D,"Electronics",Sales_Data!I:I,">0.1") -> 2
A26: 25 | B26: MINIFS | C26: Find the minimum Sales value for the "Clothing" category using MINIFS. | D26: =_xlfn.MINIFS(Sales_Data!J:J,Sales_Data!D:D,"Clothing") -> 923.67
A27: 26 | B27: MINIFS | C27: Find the minimum UnitPrice among orders from the "North" region using MINIFS. | D27: =_xlfn.MINIFS(Sales_Data!H:H,Sales_Data!C:C,"North") -> 298.69
A28: 27 | B28: MAXIFS | C28: Find the maximum Profit for the "Electronics" category using MAXIFS. | D28: =_xlfn.MAXIFS(Sales_Data!K:K,Sales_Data!D:D,"Electronics") -> 201951.71
A29: 28 | B29: MAXIFS | C29: Find the maximum Sales value among "Wholesale" customers in the "South" region, using MAXIFS. | D29: =_xlfn.MAXIFS(Sales_Data!J:J,Sales_Data!L:L,"Wholesale",Sales_Data!C:C,"South") -> 636284.16
